Traceback (most recent call last):
  File "rings/manage.py", line 60, in <module>
    start_instance(settings)
  File "rings/manage.py", line 22, in start_instance
    http_server.listen(settings["TORNADO"]["port"])
  File "/usr/lib/python2.7/dist-packages/tornado/netutil.py", line 100, in listen
    sockets = bind_sockets(port, address=address)
  File "/usr/lib/python2.7/dist-packages/tornado/netutil.py", line 265, in bind_sockets
    sock.bind(sockaddr)
  File "/usr/lib/python2.7/socket.py", line 224, in meth
    return getattr(self._sock,name)(*args)
socket.error: [Errno 98] Address already in use
Traceback (most recent call last):
  File "rings/manage.py", line 6, in <module>
    import tornado.httpserver
ImportError: No module named tornado.httpserver
Traceback (most recent call last):
  File "rings/manage.py", line 54, in <module>
    cmd = str(sys.argv[2])
IndexError: list index out of range
Traceback (most recent call last):
  File "rings/manage.py", line 55, in <module>
    port = str(sys.argv[3])
IndexError: list index out of range
WARNING:root:404 GET /favicon.ico (::1) 0.51ms
WARNING:root:404 GET /favicon.ico (::1) 0.57ms
WARNING:root:404 GET /favicon.ico (::1) 10.46ms
WARNING:root:404 GET /favicon.ico (::1) 0.55ms
WARNING:root:404 GET /favicon.ico (::1) 0.40ms
WARNING:root:404 GET /favicon.ico (::1) 0.64ms
WARNING:root:404 GET /favicon.ico (::1) 0.41ms
WARNING:root:404 GET /favicon.ico (::1) 0.44ms
WARNING:root:404 GET /favicon.ico (::1) 0.38ms
